

2024-12-02 20:02:28
1 tasks loaded from file.
1 events loaded from file.
Traceback (most recent call last):
  File "e:\Coding Projects\CS 361 Software Enineering\Innovators\Innovators\src\main.py", line 56, in <module>
    daily_overview = DailyOverview(root, calendar_app.tasks, calendar_app.events)
                     ^^^^^^^^^^^^^^^^^^^^^^^^^^^^^^^^^^^^^^^^^^^^^^^^^^^^^^^^^^^^
  File "e:\Coding Projects\CS 361 Software Enineering\Innovators\Innovators\src\ui\daily_overview.py", line 20, in __init__
    self.update_overview()
  File "e:\Coding Projects\CS 361 Software Enineering\Innovators\Innovators\src\ui\daily_overview.py", line 29, in update_overview
    due_date = datetime.strptime(task.due_date, "%Y-%m-%d")
               ^^^^^^^^^^^^^^^^^^^^^^^^^^^^^^^^^^^^^^^^^^^^
  File "C:\Users\ogw\AppData\Local\Programs\Python\Python312\Lib\_strptime.py", line 554, in _strptime_datetime
    tt, fraction, gmtoff_fraction = _strptime(data_string, format)
                                    ^^^^^^^^^^^^^^^^^^^^^^^^^^^^^^
  File "C:\Users\ogw\AppData\Local\Programs\Python\Python312\Lib\_strptime.py", line 333, in _strptime
    raise ValueError("time data %r does not match format %r" %
ValueError: time data '' does not match format '%Y-%m-%d'


2024-12-02 20:03:14
The file 'src/tasks.json' contains invalid JSON. Starting with an empty list.
Tasks saved to file: src/tasks.json
The file 'src/events.json' contains invalid JSON. Starting with an empty list.
Events saved to file: src/events.json


2024-12-02 20:06:46
0 tasks loaded from file.
0 events loaded from file.
Events saved to file: ./src/events.json
Exception in Tkinter callback
Traceback (most recent call last):
  File "C:\Users\ogw\AppData\Local\Programs\Python\Python312\Lib\tkinter\__init__.py", line 1968, in __call__
    return self.func(*args)
           ^^^^^^^^^^^^^^^^
  File "e:\Coding Projects\CS 361 Software Enineering\Innovators\Innovators\src\ui\calendar_class.py", line 331, in <lambda>
    command=lambda: self.add_task(
                    ^^^^^^^^^^^^^^
  File "e:\Coding Projects\CS 361 Software Enineering\Innovators\Innovators\src\ui\calendar_class.py", line 594, in add_task
    print(f"Event '{name}' added with start time {start_time} and end time {end_time}.")
                                                  ^^^^^^^^^^
NameError: name 'start_time' is not defined. Did you mean: 'start_date'?
Events saved to file: ./src/events.json
Exception in Tkinter callback
Traceback (most recent call last):
  File "C:\Users\ogw\AppData\Local\Programs\Python\Python312\Lib\tkinter\__init__.py", line 1968, in __call__
    return self.func(*args)
           ^^^^^^^^^^^^^^^^
  File "e:\Coding Projects\CS 361 Software Enineering\Innovators\Innovators\src\ui\calendar_class.py", line 331, in <lambda>
    command=lambda: self.add_task(
                    ^^^^^^^^^^^^^^
  File "e:\Coding Projects\CS 361 Software Enineering\Innovators\Innovators\src\ui\calendar_class.py", line 594, in add_task
    print(f"Event '{name}' added with start time {start_time} and end time {end_time}.")
                                                  ^^^^^^^^^^
NameError: name 'start_time' is not defined. Did you mean: 'start_date'?


2024-12-02 20:07:53
0 tasks loaded from file.
0 events loaded from file.
Tasks saved to file: ./src/tasks.json
Task 'A' added with start date 2024-12-02 and due date 2024-12-03.
Tasks saved to file: ./src/tasks.json
Task 'B' added with start date 2024-12-02 and due date 2024-12-03.
Tasks saved to file: ./src/tasks.json
Task 'C' added with start date 2024-12-02 and due date 2024-12-03.
3 tasks loaded from file.
Tasks saved to file: ./src/tasks.json
Exception in Tkinter callback
Traceback (most recent call last):
  File "C:\Users\ogw\AppData\Local\Programs\Python\Python312\Lib\tkinter\__init__.py", line 1968, in __call__
    return self.func(*args)
           ^^^^^^^^^^^^^^^^
  File "e:\Coding Projects\CS 361 Software Enineering\Innovators\Innovators\src\ui\calendar_class.py", line 382, in <lambda>
    command=lambda: self.edit_task(
                    ^^^^^^^^^^^^^^^
  File "e:\Coding Projects\CS 361 Software Enineering\Innovators\Innovators\src\ui\calendar_class.py", line 638, in edit_task
    self.daily_overview.update_overview()
  File "e:\Coding Projects\CS 361 Software Enineering\Innovators\Innovators\src\ui\daily_overview.py", line 28, in update_overview
    start_date = datetime.strptime(task.start_date, "%Y-%m-%d")
                 ^^^^^^^^^^^^^^^^^^^^^^^^^^^^^^^^^^^^^^^^^^^^^^
  File "C:\Users\ogw\AppData\Local\Programs\Python\Python312\Lib\_strptime.py", line 554, in _strptime_datetime
    tt, fraction, gmtoff_fraction = _strptime(data_string, format)
                                    ^^^^^^^^^^^^^^^^^^^^^^^^^^^^^^
  File "C:\Users\ogw\AppData\Local\Programs\Python\Python312\Lib\_strptime.py", line 336, in _strptime
    raise ValueError("unconverted data remains: %s" %
ValueError: unconverted data remains: 2024-12-02 20:08
Exception in Tkinter callback
Traceback (most recent call last):
  File "C:\Users\ogw\AppData\Local\Programs\Python\Python312\Lib\tkinter\__init__.py", line 1968, in __call__
    return self.func(*args)
           ^^^^^^^^^^^^^^^^
  File "e:\Coding Projects\CS 361 Software Enineering\Innovators\Innovators\src\ui\calendar_class.py", line 382, in <lambda>
    command=lambda: self.edit_task(
                    ^^^^^^^^^^^^^^^
  File "e:\Coding Projects\CS 361 Software Enineering\Innovators\Innovators\src\ui\calendar_class.py", line 610, in edit_task
    self.tasks.remove(task)
ValueError: list.remove(x): x not in list
Exception in Tkinter callback
Traceback (most recent call last):
  File "C:\Users\ogw\AppData\Local\Programs\Python\Python312\Lib\tkinter\__init__.py", line 1968, in __call__
    return self.func(*args)
           ^^^^^^^^^^^^^^^^
  File "e:\Coding Projects\CS 361 Software Enineering\Innovators\Innovators\src\ui\calendar_class.py", line 382, in <lambda>
    command=lambda: self.edit_task(
                    ^^^^^^^^^^^^^^^
  File "e:\Coding Projects\CS 361 Software Enineering\Innovators\Innovators\src\ui\calendar_class.py", line 610, in edit_task
    self.tasks.remove(task)
ValueError: list.remove(x): x not in list
Exception in Tkinter callback
Traceback (most recent call last):
  File "C:\Users\ogw\AppData\Local\Programs\Python\Python312\Lib\tkinter\__init__.py", line 1968, in __call__
    return self.func(*args)
           ^^^^^^^^^^^^^^^^
  File "e:\Coding Projects\CS 361 Software Enineering\Innovators\Innovators\src\ui\calendar_class.py", line 382, in <lambda>
    command=lambda: self.edit_task(
                    ^^^^^^^^^^^^^^^
  File "e:\Coding Projects\CS 361 Software Enineering\Innovators\Innovators\src\ui\calendar_class.py", line 610, in edit_task
    self.tasks.remove(task)
ValueError: list.remove(x): x not in list
Exception in Tkinter callback
Traceback (most recent call last):
  File "C:\Users\ogw\AppData\Local\Programs\Python\Python312\Lib\tkinter\__init__.py", line 1968, in __call__
    return self.func(*args)
           ^^^^^^^^^^^^^^^^
  File "e:\Coding Projects\CS 361 Software Enineering\Innovators\Innovators\src\ui\calendar_class.py", line 382, in <lambda>
    command=lambda: self.edit_task(
                    ^^^^^^^^^^^^^^^
  File "e:\Coding Projects\CS 361 Software Enineering\Innovators\Innovators\src\ui\calendar_class.py", line 610, in edit_task
    self.tasks.remove(task)
ValueError: list.remove(x): x not in list
Exception in Tkinter callback
Traceback (most recent call last):
  File "C:\Users\ogw\AppData\Local\Programs\Python\Python312\Lib\tkinter\__init__.py", line 1968, in __call__
    return self.func(*args)
           ^^^^^^^^^^^^^^^^
  File "e:\Coding Projects\CS 361 Software Enineering\Innovators\Innovators\src\ui\calendar_class.py", line 382, in <lambda>
    command=lambda: self.edit_task(
                    ^^^^^^^^^^^^^^^
  File "e:\Coding Projects\CS 361 Software Enineering\Innovators\Innovators\src\ui\calendar_class.py", line 610, in edit_task
    self.tasks.remove(task)
ValueError: list.remove(x): x not in list
Exception in Tkinter callback
Traceback (most recent call last):
  File "C:\Users\ogw\AppData\Local\Programs\Python\Python312\Lib\tkinter\__init__.py", line 1968, in __call__
    return self.func(*args)
           ^^^^^^^^^^^^^^^^
  File "e:\Coding Projects\CS 361 Software Enineering\Innovators\Innovators\src\ui\calendar_class.py", line 382, in <lambda>
    command=lambda: self.edit_task(
                    ^^^^^^^^^^^^^^^
  File "e:\Coding Projects\CS 361 Software Enineering\Innovators\Innovators\src\ui\calendar_class.py", line 610, in edit_task
    self.tasks.remove(task)
ValueError: list.remove(x): x not in list
Exception in Tkinter callback
Traceback (most recent call last):
  File "C:\Users\ogw\AppData\Local\Programs\Python\Python312\Lib\tkinter\__init__.py", line 1968, in __call__
    return self.func(*args)
           ^^^^^^^^^^^^^^^^
  File "e:\Coding Projects\CS 361 Software Enineering\Innovators\Innovators\src\ui\calendar_class.py", line 382, in <lambda>
    command=lambda: self.edit_task(
                    ^^^^^^^^^^^^^^^
  File "e:\Coding Projects\CS 361 Software Enineering\Innovators\Innovators\src\ui\calendar_class.py", line 610, in edit_task
    self.tasks.remove(task)
ValueError: list.remove(x): x not in list
Exception in Tkinter callback
Traceback (most recent call last):
  File "C:\Users\ogw\AppData\Local\Programs\Python\Python312\Lib\tkinter\__init__.py", line 1968, in __call__
    return self.func(*args)
           ^^^^^^^^^^^^^^^^
  File "e:\Coding Projects\CS 361 Software Enineering\Innovators\Innovators\src\ui\calendar_class.py", line 382, in <lambda>
    command=lambda: self.edit_task(
                    ^^^^^^^^^^^^^^^
  File "e:\Coding Projects\CS 361 Software Enineering\Innovators\Innovators\src\ui\calendar_class.py", line 610, in edit_task
    self.tasks.remove(task)
ValueError: list.remove(x): x not in list
Exception in Tkinter callback
Traceback (most recent call last):
  File "C:\Users\ogw\AppData\Local\Programs\Python\Python312\Lib\tkinter\__init__.py", line 1968, in __call__
    return self.func(*args)
           ^^^^^^^^^^^^^^^^
  File "e:\Coding Projects\CS 361 Software Enineering\Innovators\Innovators\src\ui\calendar_class.py", line 382, in <lambda>
    command=lambda: self.edit_task(
                    ^^^^^^^^^^^^^^^
  File "e:\Coding Projects\CS 361 Software Enineering\Innovators\Innovators\src\ui\calendar_class.py", line 610, in edit_task
    self.tasks.remove(task)
ValueError: list.remove(x): x not in list
Exception in Tkinter callback
Traceback (most recent call last):
  File "C:\Users\ogw\AppData\Local\Programs\Python\Python312\Lib\tkinter\__init__.py", line 1968, in __call__
    return self.func(*args)
           ^^^^^^^^^^^^^^^^
  File "e:\Coding Projects\CS 361 Software Enineering\Innovators\Innovators\src\ui\calendar_class.py", line 382, in <lambda>
    command=lambda: self.edit_task(
                    ^^^^^^^^^^^^^^^
  File "e:\Coding Projects\CS 361 Software Enineering\Innovators\Innovators\src\ui\calendar_class.py", line 610, in edit_task
    self.tasks.remove(task)
ValueError: list.remove(x): x not in list
Exception in Tkinter callback
Traceback (most recent call last):
  File "C:\Users\ogw\AppData\Local\Programs\Python\Python312\Lib\tkinter\__init__.py", line 1968, in __call__
    return self.func(*args)
           ^^^^^^^^^^^^^^^^
  File "e:\Coding Projects\CS 361 Software Enineering\Innovators\Innovators\src\ui\calendar_class.py", line 382, in <lambda>
    command=lambda: self.edit_task(
                    ^^^^^^^^^^^^^^^
  File "e:\Coding Projects\CS 361 Software Enineering\Innovators\Innovators\src\ui\calendar_class.py", line 610, in edit_task
    self.tasks.remove(task)
ValueError: list.remove(x): x not in list
Exception in Tkinter callback
Traceback (most recent call last):
  File "C:\Users\ogw\AppData\Local\Programs\Python\Python312\Lib\tkinter\__init__.py", line 1968, in __call__
    return self.func(*args)
           ^^^^^^^^^^^^^^^^
  File "e:\Coding Projects\CS 361 Software Enineering\Innovators\Innovators\src\ui\calendar_class.py", line 382, in <lambda>
    command=lambda: self.edit_task(
                    ^^^^^^^^^^^^^^^
  File "e:\Coding Projects\CS 361 Software Enineering\Innovators\Innovators\src\ui\calendar_class.py", line 610, in edit_task
    self.tasks.remove(task)
ValueError: list.remove(x): x not in list
Exception in Tkinter callback
Traceback (most recent call last):
  File "C:\Users\ogw\AppData\Local\Programs\Python\Python312\Lib\tkinter\__init__.py", line 1968, in __call__
    return self.func(*args)
           ^^^^^^^^^^^^^^^^
  File "e:\Coding Projects\CS 361 Software Enineering\Innovators\Innovators\src\ui\calendar_class.py", line 382, in <lambda>
    command=lambda: self.edit_task(
                    ^^^^^^^^^^^^^^^
  File "e:\Coding Projects\CS 361 Software Enineering\Innovators\Innovators\src\ui\calendar_class.py", line 610, in edit_task
    self.tasks.remove(task)
ValueError: list.remove(x): x not in list
Exception in Tkinter callback
Traceback (most recent call last):
  File "C:\Users\ogw\AppData\Local\Programs\Python\Python312\Lib\tkinter\__init__.py", line 1968, in __call__
    return self.func(*args)
           ^^^^^^^^^^^^^^^^
  File "e:\Coding Projects\CS 361 Software Enineering\Innovators\Innovators\src\ui\calendar_class.py", line 382, in <lambda>
    command=lambda: self.edit_task(
                    ^^^^^^^^^^^^^^^
  File "e:\Coding Projects\CS 361 Software Enineering\Innovators\Innovators\src\ui\calendar_class.py", line 610, in edit_task
    self.tasks.remove(task)
ValueError: list.remove(x): x not in list
Exception in Tkinter callback
Traceback (most recent call last):
  File "C:\Users\ogw\AppData\Local\Programs\Python\Python312\Lib\tkinter\__init__.py", line 1968, in __call__
    return self.func(*args)
           ^^^^^^^^^^^^^^^^
  File "e:\Coding Projects\CS 361 Software Enineering\Innovators\Innovators\src\ui\calendar_class.py", line 382, in <lambda>
    command=lambda: self.edit_task(
                    ^^^^^^^^^^^^^^^
  File "e:\Coding Projects\CS 361 Software Enineering\Innovators\Innovators\src\ui\calendar_class.py", line 610, in edit_task
    self.tasks.remove(task)
ValueError: list.remove(x): x not in list


2024-12-02 20:10:15
The file 'src/tasks.json' contains invalid JSON. Starting with an empty list.
Tasks saved to file: src/tasks.json
0 events loaded from file.
Exception in Tkinter callback
Traceback (most recent call last):
  File "c:\Users\ogw\AppData\Local\Programs\Python\Python312\Lib\tkinter\__init__.py", line 1968, in __call__
    return self.func(*args)
           ^^^^^^^^^^^^^^^^
  File "e:\Coding Projects\CS 361 Software Enineering\Innovators\Innovators\src\ui\calendar_class.py", line 331, in <lambda>
    command=lambda: self.add_task(
                    ^^^^^^^^^^^^^^
  File "e:\Coding Projects\CS 361 Software Enineering\Innovators\Innovators\src\ui\calendar_class.py", line 555, in add_task
    if self.tasks[0].priority != "High":
       ~~~~~~~~~~^^^
IndexError: list index out of range
Tasks saved to file: ./src/tasks.json
Task 'Bowie' added with start date 2024-12-02 and due date 2024-12-03.
Tasks saved to file: ./src/tasks.json
Task 'b' added with start date 2024-12-02 and due date 2024-12-03.
Tasks saved to file: ./src/tasks.json
Task 'a' added with start date 2024-12-02 and due date 2024-12-03.
Tasks saved to file: ./src/tasks.json
Task 'c' added with start date 2024-12-02 and due date 2024-12-03.
4 tasks loaded from file.
Tasks saved to file: ./src/tasks.json
Exception in Tkinter callback
Traceback (most recent call last):
  File "c:\Users\ogw\AppData\Local\Programs\Python\Python312\Lib\tkinter\__init__.py", line 1968, in __call__
    return self.func(*args)
           ^^^^^^^^^^^^^^^^
  File "e:\Coding Projects\CS 361 Software Enineering\Innovators\Innovators\src\ui\calendar_class.py", line 382, in <lambda>
    command=lambda: self.edit_task(
                    ^^^^^^^^^^^^^^^
  File "e:\Coding Projects\CS 361 Software Enineering\Innovators\Innovators\src\ui\calendar_class.py", line 638, in edit_task
    self.daily_overview.update_overview()
  File "e:\Coding Projects\CS 361 Software Enineering\Innovators\Innovators\src\ui\daily_overview.py", line 28, in update_overview
    start_date = datetime.strptime(task.start_date, "%Y-%m-%d")
                 ^^^^^^^^^^^^^^^^^^^^^^^^^^^^^^^^^^^^^^^^^^^^^^
  File "c:\Users\ogw\AppData\Local\Programs\Python\Python312\Lib\_strptime.py", line 554, in _strptime_datetime
    tt, fraction, gmtoff_fraction = _strptime(data_string, format)
                                    ^^^^^^^^^^^^^^^^^^^^^^^^^^^^^^
  File "c:\Users\ogw\AppData\Local\Programs\Python\Python312\Lib\_strptime.py", line 336, in _strptime
    raise ValueError("unconverted data remains: %s" %
ValueError: unconverted data remains: 2024-12-02 20:11
4 tasks loaded from file.


2024-12-02 20:13:27
4 tasks loaded from file.
0 events loaded from file.
Traceback (most recent call last):
  File "e:\Coding Projects\CS 361 Software Enineering\Innovators\Innovators\src\main.py", line 56, in <module>
    daily_overview = DailyOverview(root, calendar_app.tasks, calendar_app.events)
                     ^^^^^^^^^^^^^^^^^^^^^^^^^^^^^^^^^^^^^^^^^^^^^^^^^^^^^^^^^^^^
  File "e:\Coding Projects\CS 361 Software Enineering\Innovators\Innovators\src\ui\daily_overview.py", line 20, in __init__
    self.update_overview()
  File "e:\Coding Projects\CS 361 Software Enineering\Innovators\Innovators\src\ui\daily_overview.py", line 28, in update_overview
    start_date = datetime.strptime(task.start_date, "%Y-%m-%d")
                 ^^^^^^^^^^^^^^^^^^^^^^^^^^^^^^^^^^^^^^^^^^^^^^
  File "C:\Users\ogw\AppData\Local\Programs\Python\Python312\Lib\_strptime.py", line 554, in _strptime_datetime
    tt, fraction, gmtoff_fraction = _strptime(data_string, format)
                                    ^^^^^^^^^^^^^^^^^^^^^^^^^^^^^^
  File "C:\Users\ogw\AppData\Local\Programs\Python\Python312\Lib\_strptime.py", line 336, in _strptime
    raise ValueError("unconverted data remains: %s" %
ValueError: unconverted data remains: 2024-12-02 20:11


2024-12-02 20:17:59
The file 'src/tasks.json' contains invalid JSON. Starting with an empty list.
Tasks saved to file: src/tasks.json
The file 'src/events.json' contains invalid JSON. Starting with an empty list.
Events saved to file: src/events.json
Tasks saved to file: ./src/tasks.json
Task 'a' added with start date 2024-12-02 and due date 2024-12-03.
Exception in Tkinter callback
Traceback (most recent call last):
  File "C:\Users\ogw\AppData\Local\Programs\Python\Python312\Lib\tkinter\__init__.py", line 1968, in __call__
    return self.func(*args)
           ^^^^^^^^^^^^^^^^
  File "e:\Coding Projects\CS 361 Software Enineering\Innovators\Innovators\src\ui\calendar_class.py", line 331, in <lambda>
    command=lambda: self.add_task(
                    ^^^^^^^^^^^^^^
  File "e:\Coding Projects\CS 361 Software Enineering\Innovators\Innovators\src\ui\calendar_class.py", line 559, in add_task
    if self.tasks[i].priority != "High":
       ~~~~~~~~~~^^^
IndexError: list index out of range
Tasks saved to file: ./src/tasks.json
Task 'c' added with start date 2024-12-02 and due date 2024-12-03.
Tasks saved to file: ./src/tasks.json
Task 'b' added with start date 2024-12-02 and due date 2024-12-03.
3 tasks loaded from file.
Tasks saved to file: ./src/tasks.json


2024-12-02 22:16:15
3 tasks loaded from file.
0 events loaded from file.


2024-12-02 22:44:29
3 tasks loaded from file.
0 events loaded from file.
Tasks saved to file: ./src/tasks.json
Task 'A' added with start date 2024-12-02 and due date 2024-12-03.
Tasks saved to file: ./src/tasks.json
Task 'E' added with start date 2024-12-02 and due date 2024-12-03.


2024-12-02 22:47:09
5 tasks loaded from file.
0 events loaded from file.


2024-12-02 22:47:36
The file 'src/tasks.json' contains invalid JSON. Starting with an empty list.
Tasks saved to file: src/tasks.json
0 events loaded from file.
Tasks saved to file: ./src/tasks.json
Task 'A' added with start date 2024-12-02 and due date 2024-12-03.
Tasks saved to file: ./src/tasks.json
Task 'C' added with start date 2024-12-02 and due date 2024-12-03.
Tasks saved to file: ./src/tasks.json
Task 'B' added with start date 2024-12-02 and due date 2024-12-03.


2024-12-02 23:18:24
3 tasks loaded from file.
0 events loaded from file.
Tasks saved to file: ./src/tasks.json
Task 'MedC' added with start date 2024-12-02 and due date 2024-12-03.


2024-12-04 18:15:45
4 tasks loaded from file.
0 events loaded from file.
